## 回调地狱
登录 -> 获取用户信息 -> 获取用户菜单

**如果使用Ajax来写, 伪代码如下:**
```js
$.ajax({
        url: '/login',
        data: loginForm,
        success: function (data) {
            // 登录成功
            $.ajax({
                url: '/getInfo',
                success: function (data) {
                    // 获取用户信息成功
                    $.ajax({
                        url: '/getMenus',
                        success: function (data) {
                            // 获取动态菜单成功
                        }
                    })
                }
            })
        }
    })
```
原生的Ajax, 异步任务执行的逻辑和处理的逻辑写在一起,
导致如果有多个网络请求, 并且多个请求存在依赖关系,<br/>就会造成**回调地狱**.
最终如果某个任务失败, 其他任务就不会执行了.<br/>
只要是异步任务, 然后多个异步任务之间存在依存关系, 基本上都会存在**回调地狱**的问题, 将来的代码不好维护, 都是需要解决的.<br/>
**回调地狱**是一个很常见的问题, 在开发中, 可以使用**Promise**来解决这个问题.


## Promise
<h4>我们希望能够将异步任务执行的代码和处理的代码分离开, Promise就是一种异步编程的解决方案工具</h4>
登录 -> 获取用户信息 -> 获取用户菜单

**如果使用Promise来写, 伪代码如下:**
```js
    /**
     * 登录 异步耗时操作
     * @param resolve
     * @param reject
     */
    function login(resolve, reject) {
        setTimeout(() => {
            // 生成一个随机数
            let number = Math.random();
            if (number > 0.5) {
                // 登录成功, 利用 resolve 函数将登录成功的结果扔出
                resolve('登录成功');
            } else {
                // 登陆失败, 利用 reject 函数将登录失败的结果扔出
                reject('登录失败');
            }
        }, 1000);
    }
    /**
     * 获取用户信息 异步耗时操作
     * @param resolve
     * @param reject
     */
    function getInfo(resolve, reject) {
        setTimeout(() => {
            // 生成一个随机数
            let number = Math.random();
            if (number > 0.5) {
                // 获取信息成功, 利用 resolve 函数将登录成功的结果扔出
                resolve('获取信息成功');
            } else {
                // 获取信息失败, 利用 reject 函数将登录失败的结果扔出
                reject('获取信息失败');
            }
        }, 1000);
    }
    /**
     * 获取菜单 异步耗时操作
     * @param resolve
     * @param reject
     */
    function getMenus(resolve, reject){
        setTimeout(() => {
            // 生成一个随机数
            let number = Math.random();
            if (number > 0.5) {
                // 获取菜单成功, 利用 resolve 函数将登录成功的结果扔出
                resolve('获取菜单成功');
            } else {
                // 获取菜单失败, 利用 reject 函数将登录失败的结果扔出
                reject('获取菜单失败');
            }
        }, 1000);
    }

    new Promise(login).then(data => {
        // 如果 login 将来执行成功 (即 resolve 方法抛出执行结果时)
        console.log("login: ", data);
        return new Promise(getInfo);
    }).then(data => {
        // getInfo 将来执行成功, 进入此代码块中
        console.log("getInfo: ", data);
        return new Promise(getMenus);
    }).then(data => {
        console.log("getMenus: ", data);
    }).catch(err => {
        // 如果上面任意一个出现异常, 都会进入到最近的 catch 代码块中
        console.error("err: ", err);
    })
```
Promise 中, 执行成功就通过 resolve 将成功的结果抛出; 执行失败就通过 reject 将失败的结果抛出;<br/>
在 Promise 中, 只管抛出结果.<br/>
如果是 resolve 中, 则进入到接下来的 then 中对异步任务的执行结果进行处理;<br/>
如果是 reject 执行了, 则进入到 catch 代码块中对异常的结果进行处理.

## then
**then 方法参数**<br/>
then 方法中, 可以传递两个回调函数, 第一个是成功的回调函数, 第二个是失败的回调函数, 如果没有传递第二个参数, 那么可以在 catch 中处理失败.
```js
/**
     * 登录 异步耗时操作
     * @param resolve
     * @param reject
     */
    function login(resolve, reject) {
        setTimeout(() => {
            // 生成一个随机数
            let number = Math.random();
            if (number > 0.5) {
                // 登录成功, 利用 resolve 函数将登录成功的结果扔出
                resolve('登录成功');
            } else {
                // 登陆失败, 利用 reject 函数将登录失败的结果扔出
                reject('登录失败');
            }
        }, 1000);
    }

    new Promise(login).then(data => {
        // 如果 login 将来执行成功 (即 resolve 方法抛出执行结果时)
        console.log("login: ", data);
    },err => {
        console.error("err: ", err);
    })
```
<br/>

<h3>then 方法返回值</h3>
**返回Promise**<br/>
前面的例子, 返回的就是 Promise. 这样的话, 下一个 then 的主语其实就是上一个 then 返回的 Promise.
```js
A.then(data => {
    xxx;
    return B;
}).then(data => {
    xxx
})
```
由于在A的 then 中返回了B, 所以第二个 then 的主语, 其实是B, 不是A(假设A和B都是 Promise对象)<br/>

**返回字符串**<br/>
then 方法中就可以返回一个字符串, 此时可以一直 then 下去, 所以的 then 方法此时都是同一个主语.
```js
/**
     * 登录 异步耗时操作
     * @param resolve
     * @param reject
     */
    function login(resolve, reject) {
        setTimeout(() => {
            // 生成一个随机数
            let number = Math.random();
            if (number > 0.5) {
                // 登录成功, 利用 resolve 函数将登录成功的结果扔出
                resolve('登录成功');
            } else {
                // 登陆失败, 利用 reject 函数将登录失败的结果扔出
                reject('登录失败');
            }
        }, 1000);
    }

    new Promise(login).then(data => {
        // 如果 login 将来执行成功 (即 resolve 方法抛出执行结果时)
        console.log("then1: ", data);
        return data;
    }).then(data => {
        console.log("then2: ", data);
        return data;
    }).then(data => {
        console.log("then3: ", data);
    }).catch(err => {
        console.log("err: ", err);
    })
```
此时, 三个 then 都是同一个主语, 因为在 then 中没有返回新的 Promise 对象.<br/>
每一个 then 的参数, 都是上一个 then 的返回值.
<br/>

**抛出异常**<br/>
then 方法中也可以抛出异常
```js
/**
     * 登录 异步耗时操作
     * @param resolve
     * @param reject
     */
    function login(resolve, reject) {
        setTimeout(() => {
            // 生成一个随机数
            let number = Math.random();
            if (number > 0.5) {
                // 登录成功, 利用 resolve 函数将登录成功的结果扔出
                resolve('登录成功');
            } else {
                // 登陆失败, 利用 reject 函数将登录失败的结果扔出
                reject('登录失败');
            }
        }, 1000);
    }

    new Promise(login).then(data => {
        // 如果 login 将来执行成功 (即 resolve 方法抛出执行结果时)
        console.log("then1: ", data);
        return data;
    }).then(data => {
        console.log("then2: ", data);
        return data;
    }).then(data => {
        throw new Error('出错了');
    }).catch(err => {
        console.log("err: ", err);
    })
```
then 中还可以直接抛出异常, 抛出异常的话就会进入到 catch 中.<br/>

## catch
catch 并不是必须存在的, 也可以直接在 then 中写两个回调函数, 第二个回调函数就是用来处理 catch 的,<br/>
在更多的情况下, 都是使用 reject 函数来单独写 catch 的.<br/>

进入到 catch 中, 分为两种情况:<br/>
1, Promise 在执行的过程中, 通过 reject 返回数据.<br/>
2, then 中抛出异常.<br/>
进入 catch 的时候, 都是选择就近的进入.

## finally
无论最终执行的是 then 还是 catch, 反正都是会进入到 finally 代码块中:
```js
/**
     * 登录 异步耗时操作
     * @param resolve
     * @param reject
     */
    function login(resolve, reject) {
        setTimeout(() => {
            // 生成一个随机数
            let number = Math.random();
            if (number > 0.5) {
                // 登录成功, 利用 resolve 函数将登录成功的结果扔出
                resolve('登录成功');
            } else {
                // 登陆失败, 利用 reject 函数将登录失败的结果扔出
                reject('登录失败');
            }
        }, 1000);
    }

    new Promise(login).then(data => {
        // 如果 login 将来执行成功 (即 resolve 方法抛出执行结果时)
        console.log("then1: ", data);
        return data;
    }).then(data => {
        console.log("then2: ", data);
        return data;
    }).then(data => {
        throw new Error('出错了');
    }).catch(err => {
        console.log("err: ", err);
    }).finally(() => {
        console.log("over!");
    })
```
类似于 Java 中的 finally, 就是前面无论执行的是 catch 还是 then, 最终都会执行 finally.
不过不同于 Java 中的 finally, 前端的 finally 执行完成之后, 还可以继续 then:
```js
/**
     * 登录 异步耗时操作
     * @param resolve
     * @param reject
     */
    function login(resolve, reject) {
        setTimeout(() => {
            // 生成一个随机数
            let number = Math.random();
            if (number > 0.5) {
                // 登录成功, 利用 resolve 函数将登录成功的结果扔出
                resolve('登录成功');
            } else {
                // 登陆失败, 利用 reject 函数将登录失败的结果扔出
                reject('登录失败');
            }
        }, 1000);
    }

    new Promise(login).then(data => {
        // 如果 login 将来执行成功 (即 resolve 方法抛出执行结果时)
        console.log("then1: ", data);
        return data;
    }).then(data => {
        console.log("then2: ", data);
        return data;
    }).then(data => {
        throw new Error('出错了');
    }).catch(err => {
        console.log("err: ", err);
    }).finally(() => {
        console.log("over!");
    }).then(() => {
        console.log("then3: ", data);
    })
```
finally 之后还可以继续 then.

## 静态方法
### Promise.resolve()
返回一个带有给定值解析后的 Promise 对象：
```js
    let a1 = promise.resolve("Hello promise");
    a1.then(data => {
        console.log("data: ", data);
    }).catch(err => {
        // 需要 then 抛出异常, 才会进入 catch
        console.error("err: ", err);
    })
```

### Promise.reject()
返回一个带有 reject 原因的 Promise 对象:
```js
    function resolved() {
        console.log('resolved');
    }
    function rejected(err) {
        console.log("err: ", err);
    }

    let a1 = Promise.reject("出错！");
    // a1.then(resolved, rejected);
    a1.then(resolved).catch(rejected);
```
a1 只会进入到 catch 中.

### Promise.all()
这个静态方法接受多个 Promise 对象, 并且只返回一个 Promise 实例. all 方法中会传入多个 Promise 实例,<br/>
他会等所有的 Promise 对象都 resolve 之后, 才会进入到 then 中, 否则只要参数中的 Promise 中有一个对象 reject 了,<br/>
就会进入到 catch 中.<br/>
**简而言之, 所有的 Promise 都成功, 进入 then. 有一个 Promise 失败了, 就会进入 catch.**
```js
    let a1 = Promise.resolve('sihai');
    let a2 = 88;
    let a3 = new Promise((resolve, reject) => {
        setTimeout(resolve, 1000, 'sihai1');
    });

    Promise.all([a1, a2, a3]).then(data => {
        // 三个参数都是 resolve, 就会进入到 then 中
        console.log("data: ",data);
    }).catch(err => {
        // 三个参数有一个是 reject, 就会进入到 catch 中
        console.err("err: ",err);
    })
```
all 方法能够帮助我们确保多个异步任务同时执行成功.

### Promise.race()
这个也可以同时接受多个 Promise 对象, 一旦参数中的 Promise 对象 resolve 或者 reject, 就会进入到 resolve 或者 reject 中.<br/>
**简而言之, 参数中只要有一个执行成功或者失败, 就可以了, 不会等待别的 Promise 对象, 其他的执行慢了的 Promise 对象就会直接被抛弃**
```js
    let a1 = new Promise((resolve, reject) => {
        setTimeout(resolve, 100, 'sihai1');
    });
    let a2 = new Promise((resolve, reject) => {
        setTimeout(resolve, 200, 'sihai2');
    });

    Promise.race([a1, a2]).then(data => {
        console.log("data: ", data);
    }).catch(err => {
        console.err("err: ", err);
    })
```
哪个对象执行的快, 最终进入 then 的就是谁, 剩下的 Promise 对象则被抛弃.